Workbook

Sheet 数据
A1: 月份 | B1: 全部 | C1: 特殊法人 | D1: 自然人 | E1: 法人 | F1: 集团客户 | G1: 非集团客户 | H1: 集团占比 | I1: 期末权益(万元） | J1: 权益变动(万元） | K1: 环比 | L1: 净入金（万元） | M1: 盈亏（万元） | N1: 日均持仓量（万手） | O1: 成交数量（万手） | P1: 日均成交量（万手） | Q1: 成交持仓比 | R1: 交易日 | S1: 开户数 | T1: 客户总数 | U1: 交易客户数 | V1: 销户数 | W1: 手续费（万元） | X1: 留存手续费（万元） | Y1: 辅助列1 | Z1: 辅助列2
A2: 2401W1 | B2: 1.9669805 | C2: 0.084172726 | D2: 0.57506993 | E2: 1.3077378 | F2: 1.1654501 | G2: =(B2-F2) -> 0.80153039 | H2: =F2/B2 -> 0.5925072 | I2: 1.9486007 | J2: -0.74804232 | K2: -0.3184245 | L2: 919.18795 | M2: -734.2885 | N2: 1.018675 | O2: 1.9716 | P2: 0.4929 | Q2: =表1[[#This Row],[日均成交量（万手）]]/表1[[#This Row],[日均持仓量（万手）]] -> 0.48386384 | R2: 4 | S2: 25 | T2: 1881 | U2: 118 | V2: 0 | W2: 28.144415 | X2: 7.097382 | Y2: 20000 | Z2: 0
A3: 2401W2 | B3: 2.5272123 | C3: 0.11630272 | D3: 0.52910689 | E3: 1.8818027 | F3: 1.7395133 | G3: =(B3-F3) -> 0.78769902 | H3: =F3/B3 -> 0.68831308 | I3: 1.9607585 | J3: =表1[[#This Row],[期末权益(万元）]]-I2 -> 0.012157765 | K3: =表1[[#This Row],[权益变动(万元）]]/I2 -> 0.0062392283 | L3: -1034.0371 | M3: 1030.742 | N3: 1.48138 | O3: 3.9447 | P3: 0.78894 | Q3: =表1[[#This Row],[日均成交量（万手）]]/表1[[#This Row],[日均持仓量（万手）]] -> 0.53257098 | R3: 5 | S3: 28 | T3: =T2+S3-V3 -> 1909 | U3: 127 | V3: 0 | W3: 50.102217 | X3: 9.136076 | Y3: 20000 | Z3: 0
A4: 2401W3 | B4: 1.9980174 | C4: 0.11986177 | D4: 0.55672959 | E4: 1.3214261 | F4: 1.1747291 | G4: =(B4-F4) -> 0.82328838 | H4: =F4/B4 -> 0.58794735 | I4: 2.1169211 | J4: =表1[[#This Row],[期末权益(万元）]]-I3 -> 0.15616258 | K4: =表1[[#This Row],[权益变动(万元）]]/I3 -> 0.079643963 | L4: 2390.4427 | M4: -726.6099 | N4: 1.92398 | O4: 4.3072 | P4: 0.86144 | Q4: =表1[[#This Row],[日均成交量（万手）]]/表1[[#This Row],[日均持仓量（万手）]] -> 0.44773854 | R4: 5 | S4: 18 | T4: =T3+S4-V4 -> 1927 | U4: 138 | V4: 0 | W4: 62.494992 | X4: 10.242538 | Y4: 20000 | Z4: 0
A5: 2401W4 | B5: 2.5974169 | C5: 0.10197175 | D5: 0.55925608 | E5: 1.9361891 | F5: 1.7830796 | G5: =(B5-F5) -> 0.81433733 | H5: =F5/B5 -> 0.68648186 | I5: 3.649802 | J5: =表1[[#This Row],[期末权益(万元）]]-I4 -> 1.5328809 | K5: =表1[[#This Row],[权益变动(万元）]]/I4 -> 0.72410865 | L5: 15792.661 | M5: -362.0485 | N5: 2.58344 | O5: 4.4527 | P5: 0.89054 | Q5: =表1[[#This Row],[日均成交量（万手）]]/表1[[#This Row],[日均持仓量（万手）]] -> 0.34471093 | R5: 5 | S5: 20 | T5: =T4+S5-V5 -> 1947 | U5: 137 | V5: 0 | W5: 74.903706 | X5: 9.925907 | Y5: 20000 | Z5: 0
A6: 2402W1 | B6: 2.9387115 | C6: 0.10242312 | D6: 0.55923936 | E6: 2.2770491 | F6: 2.1238452 | G6: =(B6-F6) -> 0.81486638 | H6: =F6/B6 -> 0.72271304 | I6: 2.853323 | J6: =表1[[#This Row],[期末权益(万元）]]-I5 -> -0.79647895 | K6: =表1[[#This Row],[权益变动(万元）]]/I5 -> -0.21822525 | L6: -9101.849 | M6: 1192.5105 | N6: 2.57416 | O6: 3.8439 | P6: 0.76878 | Q6: =表1[[#This Row],[日均成交量（万手）]]/表1[[#This Row],[日均持仓量（万手）]] -> 0.29865276 | R6: 5 | S6: 8 | T6: =T5+S6-V6 -> 1955 | U6: 133 | V6: 0 | W6: 71.026929 | X6: 8.326094 | Y6: 20000 | Z6: 0
A7: 2402W2 | B7: 2.8800696 | C7: 0.10294318 | D7: 0.56912991 | E7: 2.2079965 | F7: 2.0547028 | G7: =(B7-F7) -> 0.82536678 | H7: =F7/B7 -> 0.71342124 | I7: 2.9798684 | J7: =表1[[#This Row],[期末权益(万元）]]-I6 -> 0.1265454 | K7: =表1[[#This Row],[权益变动(万元）]]/I6 -> 0.044350183 | L7: 1532.9557 | M7: -178.253 | N7: 2.723125 | O7: 2.5818 | P7: 0.64545 | Q7: =表1[[#This Row],[日均成交量（万手）]]/表1[[#This Row],[日均持仓量（万手）]] -> 0.23702548 | R7: 4 | S7: 3 | T7: =T6+S7-V7 -> 1957 | U7: 116 | V7: 1 | W7: 74.744744 | X7: 3.384998 | Y7: 20000 | Z7: 0
A8: 2402W4 | B8: 2.7622689 | C8: 0.098345621 | D8: 0.6343794 | E8: 2.0295439 | F8: 1.878383 | G8: =(B8-F8) -> 0.88388587 | H8: =F8/B8 -> 0.68001454 | I8: 2.6330293 | J8: =表1[[#This Row],[期末权益(万元）]]-I7 -> -0.34683908 | K8: =表1[[#This Row],[权益变动(万元）]]/I7 -> -0.11639409 | L8: -3514.8711 | M8: 23.9924 | N8: 2.8789 | O8: 3.5827 | P8: 0.71654 | Q8: =表1[[#This Row],[日均成交量（万手）]]/表1[[#This Row],[日均持仓量（万手）]] -> 0.24889367 | R8: 5 | S8: 9 | T8: =T7+S8-V8 -> 1966 | U8: 126 | V8: 0 | W8: 41.986109 | X8: 5.515046 | Y8: 20000 | Z8: 0
A9: 2403W1 | B9: 2.9508832 | C9: 0.098897567 | D9: 0.63459446 | E9: 2.2173912 | F9: 2.0744397 | G9: =(B9-F9) -> 0.87644352 | H9: =F9/B9 -> 0.70298942 | I9: 2.728014 | J9: =表1[[#This Row],[期末权益(万元）]]-I8 -> 0.094984695 | K9: =表1[[#This Row],[权益变动(万元）]]/I8 -> 0.036074302 | L9: -970.64464 | M9: 1869.7075 | N9: 2.39316 | O9: 4.0746 | P9: 0.81492 | Q9: =表1[[#This Row],[日均成交量（万手）]]/表1[[#This Row],[日均持仓量（万手）]] -> 0.34052048 | R9: 5 | S9: 15 | T9: =T8+S9-V9 -> 1981 | U9: 134 | V9: 0 | W9: 62.30441 | X9: 6.392509 | Y9: 20000 | Z9: 0
A10: 2403W2 | B10: 2.7317647 | C10: 0.099022138 | D10: 0.6605461 | E10: 1.9721964 | F10: 1.8292062 | G10: =(B10-F10) -> 0.90255847 | H10: =F10/B10 -> 0.66960607 | I10: 2.7363296 | J10: =表1[[#This Row],[期末权益(万元）]]-I9 -> 0.0083155632 | K10: =表1[[#This Row],[权益变动(万元）]]/I9 -> 0.0030482113 | L10: -262.75759 | M10: 388.8755 | N10: 2.3235 | O10: 6.2168 | P10: 1.24336 | Q10: =表1[[#This Row],[日均成交量（万手）]]/表1[[#This Row],[日均持仓量（万手）]] -> 0.53512374 | R10: 5 | S10: 25 | T10: =T9+S10-V10 -> 2006 | U10: 153 | V10: 0 | W10: 55.113781 | X10: 10.837274 | Y10: 20000 | Z10: 0
A11: 2403W3 | B11: 2.8451897 | C11: 0.098891881 | D11: 0.69561739 | E11: 2.0506804 | F11: 1.9075181 | G11: =(B11-F11) -> 0.93767159 | H11: =F11/B11 -> 0.67043618 | I11: 2.8395481 | J11: =表1[[#This Row],[期末权益(万元）]]-I10 -> 0.10321852 | K11: =表1[[#This Row],[权益变动(万元）]]/I10 -> 0.037721522 | L11: 1162.7346 | M11: -51.819 | N11: 2.629 | O11: 6.6735 | P11: 1.3347 | Q11: =表1[[#This Row],[日均成交量（万手）]]/表1[[#This Row],[日均持仓量（万手）]] -> 0.50768353 | R11: 5 | S11: 28 | T11: =T10+S11-V11 -> 2034 | U11: 161 | V11: 0 | W11: 58.527634 | X11: 17.192052 | Y11: 20000 | Z11: 0
A12: 2403W4 | B12: 2.8229914 | C12: 0.099285048 | D12: 0.69867507 | E12: 2.0250313 | F12: 1.8817129 | G12: =(B12-F12) -> 0.94127853 | H12: =F12/B12 -> 0.66656699 | I12: 2.6990949 | J12: =表1[[#This Row],[期末权益(万元）]]-I11 -> -0.14045317 | K12: =表1[[#This Row],[权益变动(万元）]]/I11 -> -0.049463212 | L12: -3077.6877 | M12: 1596.3985 | N12: 2.71824 | O12: 11.8292 | P12: 2.36584 | Q12: =表1[[#This Row],[日均成交量（万手）]]/表1[[#This Row],[日均持仓量（万手）]] -> 0.87035729 | R12: 5 | S12: 26 | T12: =T11+S12-V12 -> 2060 | U12: 171 | V12: 0 | W12: 77.442008 | X12: 19.349449 | Y12: 20000 | Z12: 0
A13: 2403W5 | B13: 2.5764271 | C13: 0.099744203 | D13: 0.61436689 | E13: 1.862316 | F13: 1.7186125 | G13: =(B13-F13) -> 0.85781455 | H13: =F13/B13 -> 0.66705265 | I13: 2.3240292 | J13: =表1[[#This Row],[期末权益(万元）]]-I12 -> -0.37506576 | K13: =表1[[#This Row],[权益变动(万元）]]/I12 -> -0.13895983 | L13: -2644.3333 | M13: -1121.9225 | N13: 2.63714 | O13: 7.1065 | P13: 1.4213 | Q13: =表1[[#This Row],[日均成交量（万手）]]/表1[[#This Row],[日均持仓量（万手）]] -> 0.53895508 | R13: 5 | S13: 26 | T13: =T12+S13-V13 -> 2086 | U13: 188 | V13: 0 | W13: 71.228335 | X13: 14.64372 | Y13: 20000 | Z13: 0
A14: 2404W1 | B14: 2.4848114 | C14: 0.099233086 | D14: 0.57212245 | E14: 1.8134559 | F14: 1.6696935 | G14: =(B14-F14) -> 0.81511789 | H14: =F14/B14 -> 0.67195986 | I14: 2.6772485 | J14: =表1[[#This Row],[期末权益(万元）]]-I13 -> 0.35321932 | K14: =表1[[#This Row],[权益变动(万元）]]/I13 -> 0.15198575 | L14: 3633.6802 | M14: -90.434 | N14: 2.9877 | O14: 2.5825 | P14: 0.86083333 | Q14: =表1[[#This Row],[日均成交量（万手）]]/表1[[#This Row],[日均持仓量（万手）]] -> 0.28812576 | R14: 3 | S14: 12 | T14: =T13+S14-V14 -> 2097 | U14: 185 | V14: 1 | W14: 20.877004 | X14: 8.521983 | Y14: 20000 | Z14: 0
... A80: 2507W4 | B80: 4.7375393 | C80: 1.9793396 | D80: 1.6657297 | E80: 1.0924699 | F80: 1.0630412 | G80: =(B80-F80) -> 3.6744981 | H80: =F80/B80 -> 0.22438678 | I80: 4.8505254 | J80: =表1[[#This Row],[期末权益(万元）]]-I79 -> 0.1575679 | K80: =表1[[#This Row],[权益变动(万元）]]/I79 -> 0.033575394 | L80: 361.98433 | M80: 1366.964 | N80: 5.11304 | O80: 12.6738 | P80: 2.53476 | Q80: =表1[[#This Row],[日均成交量（万手）]]/表1[[#This Row],[日均持仓量（万手）]] -> 0.49574421 | R80: 5 | S80: 12 | T80: =T79+S80-V80 -> 5389 | U80: 646 | V80: 2 | W80: 195.149 | X80: 120.45128 | Y80: 30000 | Z80: 0
A81: 2508W1 | B81: 4.7202053 | C81: 1.9430781 | D81: 1.5955014 | E81: 1.1816258 | F81: 1.1504097 | G81: =(B81-F81) -> 3.5697956 | H81: =F81/B81 -> 0.24372026 | I81: 4.5937399 | J81: =表1[[#This Row],[期末权益(万元）]]-I80 -> -0.25678552 | K81: =表1[[#This Row],[权益变动(万元）]]/I80 -> -0.052939733 | L81: -294.0544 | M81: -2065.1725 | N81: 5.65244 | O81: 11.7546 | P81: =O81/R81 -> 2.35092 | Q81: =表1[[#This Row],[日均成交量（万手）]]/表1[[#This Row],[日均持仓量（万手）]] -> 0.41591242 | R81: 5 | S81: 8 | T81: =T80+S81-V81 -> 5394 | U81: 598 | V81: 3 | W81: 155.76466 | X81: 87.371232 | Y81: 30000 | Z81: 0
A82: 2508W2 | B82: 4.7826727 | C82: 1.8732078 | D82: 1.6327524 | E82: 1.2767125 | F82: 1.2462511 | G82: =(B82-F82) -> 3.5364216 | H82: =F82/B82 -> 0.26057629 | I82: 4.6482954 | J82: =表1[[#This Row],[期末权益(万元）]]-I81 -> 0.054555451 | K82: =表1[[#This Row],[权益变动(万元）]]/I81 -> 0.011876043 | L82: 888.40324 | M82: -203.6335 | N82: 5.56002 | O82: 7.1381 | P82: 1.42762 | Q82: =表1[[#This Row],[日均成交量（万手）]]/表1[[#This Row],[日均持仓量（万手）]] -> 0.25676526 | R82: 5 | S82: 3 | T82: =T81+S82-V82 -> 5394 | U82: 532 | V82: 3 | W82: 69.21058 | X82: 33.440027 | Y82: 30000 | Z82: 0
A83: 2508W3 | B83: 4.7728395 | C83: 1.8394383 | D83: 1.3939996 | E83: 1.5394016 | F83: 1.5111204 | G83: =(B83-F83) -> 3.2617191 | H83: =F83/B83 -> 0.31660825 | I83: 4.5154872 | J83: =表1[[#This Row],[期末权益(万元）]]-I82 -> -0.13280822 | K83: =表1[[#This Row],[权益变动(万元）]]/I82 -> -0.028571382 | L83: -839.52103 | M83: -405.135 | N83: 5.14838 | O83: 6.2832 | P83: 1.25664 | Q83: =表1[[#This Row],[日均成交量（万手）]]/表1[[#This Row],[日均持仓量（万手）]] -> 0.24408455 | R83: 5 | S83: 7 | T83: =T82+S83-V83 -> 5399 | U83: 503 | V83: 2 | W83: 62.59588 | X83: 29.490962 | Y83: 30000 | Z83: 0
A84: 2508W4 | B84: 4.6830676 | C84: 1.8102922 | D84: 1.3242847 | E84: 1.5484907 | F84: 1.5237259 | G84: =(B84-F84) -> 3.1593417 | H84: =F84/B84 -> 0.32536919 | I84: 4.324497 | J84: =表1[[#This Row],[期末权益(万元）]]-I83 -> -0.19099021 | K84: =表1[[#This Row],[权益变动(万元）]]/I83 -> -0.0422967 | L84: -3240.4522 | M84: 1434.818 | N84: 4.96994 | O84: 10.8077 | P84: 2.16154 | Q84: =表1[[#This Row],[日均成交量（万手）]]/表1[[#This Row],[日均持仓量（万手）]] -> 0.43492276 | R84: 5 | S84: 4 | T84: =T83+S84-V84 -> 5400 | U84: 482 | V84: 3 | W84: 66.891172 | X84: 23.288812 | Y84: 30000 | Z84: 0
A85: 2508W5 | B85: 4.2895201 | C85: 1.7932278 | D85: 1.2898582 | E85: 1.206434 | F85: 1.1840904 | G85: =(B85-F85) -> 3.1054297 | H85: =F85/B85 -> 0.27604262 | I85: 3.9020733 | J85: =表1[[#This Row],[期末权益(万元）]]-I84 -> -0.42242367 | K85: =表1[[#This Row],[权益变动(万元）]]/I84 -> -0.097681574 | L85: -2650.1539 | M85: -1658.854 | N85: 4.81218 | O85: 7.9829 | P85: 1.59658 | Q85: =表1[[#This Row],[日均成交量（万手）]]/表1[[#This Row],[日均持仓量（万手）]] -> 0.33177894 | R85: 5 | S85: 9 | T85: =T84+S85-V85 -> 5405 | U85: 459 | V85: 4 | W85: 51.609405 | X85: 16.330599 | Y85: 30000 | Z85: 0
A102: 周 | B102: 全部 | C102: 特殊法人 | D102: 自然人 | E102: 法人 | F102: 集团客户 | G102: 非集团客户 | H102: 集团占比 | I102: 期末权益(万元） | L102: 净入金（万元） | M102: 盈亏（万元） | N102: 日均持仓量（万手） | O102: 成交数量（万手） | P102: 日均成交量（万手） | Q102: 成交持仓比 | R102: 交易日 | S102: 开户数 | T102: 客户总数 | U102: 交易客户数 | V102: 销户数 | W102: 手续费（万元） | X102: 留存手续费（万元） | Y102: 辅助列1
A103: 2503W1 | B103: 4.5815539 | C103: 2.0947284 | D103: 1.344536 | E103: 1.1422895 | F103: 1.0794053 | G103: 0 | H103: 0 | I103: 4.5088193 | J103: 0 | K103: 0 | L103: 13712.331 | M103: -2140.5995 | N103: 4.614 | O103: 7.5478 | P103: =O103/R103 -> 1.50956 | R103: 5 | S103: 42 | U103: 619 | V103: 2 | W103: 118.87664 | X103: 76.42081
A104: 2503W2 | B104: 4.6138602 | C104: 2.1187414 | D104: 1.2710024 | E104: 1.2241164 | F104: 1.159528 | G104: 0 | H104: 0 | I104: 4.6111153 | J104: 0 | K104: 0 | L104: 1764.4094 | M104: -619.264 | N104: 5.18184 | O104: 9.2053 | P104: =O104/R104 -> 1.84106 | R104: 5 | S104: 47 | U104: 647 | V104: 3 | W104: 151.32488 | X104: 99.43178
A105: 2503W3 | B105: 4.9191941 | C105: 2.2183415 | D105: 1.1592415 | E105: 1.541611 | F105: 1.4758079 | G105: 0 | H105: 0 | I105: 5.0852453 | J105: 0 | K105: 0 | L105: 5316.4115 | M105: -417.2105 | N105: 5.24736 | O105: 8.453 | P105: =O105/R105 -> 1.6906 | R105: 5 | S105: 47 | U105: 640 | V105: 0 | W105: 135.85287 | X105: 90.179261
A106: 2503W4 | B106: 5.2169068 | C106: 2.2377264 | D106: 1.3035925 | E106: 1.6755879 | F106: 1.620979 | G106: 0 | H106: 0 | I106: 5.1726951 | J106: 0 | K106: 0 | L106: 842.83645 | M106: 176.4325 | N106: 5.10454 | O106: 7.1762 | P106: =O106/R106 -> 1.43524 | R106: 5 | S106: 36 | U106: 632 | V106: 1 | W106: 127.9641 | X106: 86.046234
A107: 2504W1 | B107: 4.737854 | C107: 2.2270297 | D107: 1.2915253 | E107: 1.2192989 | F107: 1.1648398 | G107: 0 | H107: 0 | I107: 4.913785 | J107: 0 | K107: 0 | L107: -1834.932 | M107: -674.012 | N107: 5.066875 | O107: 5.3834 | P107: =O107/R107 -> 1.34585 | R107: 4 | S107: 35 | U107: 608 | V107: 0 | W107: 90.878126 | X107: 61.891718
A108: 2504W2 | B108: 5.0323597 | C108: 2.3420901 | D108: 1.201157 | E108: 1.4891126 | F108: 1.434173 | G108: 0 | H108: 0 | I108: 5.0523359 | J108: 0 | K108: 0 | L108: 7934.5214 | M108: -6408.4165 | N108: 4.74094 | O108: 11.0588 | P108: =O108/R108 -> 2.21176 | R108: 5 | S108: 64 | U108: 639 | V108: 2 | W108: 138.43391 | X108: 87.673919
A109: 2504W3 | B109: 4.9749452 | C109: 2.2768392 | D109: 1.2643995 | E109: 1.4337065 | F109: 1.3794534 | G109: 0 | H109: 0 | I109: 4.7786064 | J109: 0 | K109: 0 | L109: -2778.6162 | M109: 160.931 | N109: 5.25076 | O109: 8.6732 | P109: =O109/R109 -> 1.73464 | R109: 5 | S109: 49 | U109: 622 | V109: 4 | W109: 100.18533 | X109: 61.32388
A110: 2504W4 | B110: 5.1863359 | C110: 2.2278714 | D110: 1.3133406 | E110: 1.645124 | F110: 1.5950961 | G110: 0 | H110: 0 | I110: 6.5510812 | J110: 0 | K110: 0 | L110: 17744.452 | M110: 81.056 | N110: 5.27094 | O110: 11.7543 | P110: =O110/R110 -> 2.35086 | R110: 5 | S110: 76 | U110: 630 | V110: 0 | W110: 108.00728 | X110: 61.435686
A111: 2505W1 | B111: 6.4051645 | C111: 2.2097282 | D111: 1.2872223 | E111: 2.908214 | F111: 2.8638969 | G111: 0 | H111: 0 | I111: 4.9823682 | J111: 0 | K111: 0 | L111: -14516.736 | M111: -1134.472 | N111: 4.9071667 | O111: 4.2393 | P111: =O111/R111 -> 1.4131 | R111: 3 | S111: 35 | U111: 570 | V111: 1 | W111: 39.988428 | X111: 22.348926
A112: 2505W2 | B112: 5.264558 | C112: 2.2977533 | D112: 1.3689377 | E112: 1.5978671 | F112: 1.5524094 | G112: 0 | H112: 0 | I112: 5.9145639 | J112: 0 | K112: 0 | L112: 8412.0852 | M112: 972.964 | N112: 4.902825 | O112: 4.9007 | P112: =O112/R112 -> 1.225175 | R112: 4 | S112: 39 | U112: 574 | V112: 1 | W112: 53.639711 | X112: 32.136994
A113: 2505W3 | B113: 5.6464272 | C113: 2.3425733 | D113: 1.4048776 | E113: 1.8989764 | F113: 1.8513413 | G113: 0 | H113: 0 | I113: 5.3875493 | J113: 0 | K113: 0 | L113: -10051.163 | M113: 4918.3075 | N113: 4.78098 | O113: 10.2866 | P113: =O113/R113 -> 2.05732 | R113: 5 | S113: 53 | U113: 643 | V113: 1 | W113: 113.84284 | X113: 67.228931
A114: 2505W4 | B114: 5.3034048 | C114: 2.3515332 | D114: 1.5154601 | E114: 1.4364114 | F114: 1.3930562 | G114: 0 | H114: 0 | I114: 5.3118632 | J114: 0 | K114: 0 | L114: -277.29312 | M114: -373.532 | N114: 4.84762 | O114: 8.6583 | P114: =O114/R114 -> 1.73166 | R114: 5 | S114: 60 | U114: 635 | V114: 4 | W114: 97.226052 | X114: 57.326233
... A128: 2508W5 | B128: 4.2895201 | C128: 1.7932278 | D128: 1.2898582 | E128: 1.206434 | F128: 1.1840904 | G128: 0 | H128: 0 | I128: 3.9020733 | J128: 0 | K128: 0 | L128: -2650.1539 | M128: -1658.854 | N128: 4.81218 | O128: 7.9829 | P128: =O128/R128 -> 1.59658 | R128: 5 | S128: 9 | U128: 459 | V128: 4 | W128: 51.609405 | X128: 16.330599
P137: 10000

Sheet 数据表
A1: 客户属性日均权益（亿元）
A2: 月份 | B2: 全部 | C2: 机构 | D2: 个人 | E2: 产业
A3: 2506W2 | B3: 4.8594317 | C3: 2.0701277 | D3: 1.4955002 | E3: 1.2938038
A4: 2506W3 | B4: 4.8539346 | C4: 2.0842188 | D4: 1.4870598 | E4: 1.2826561
A5: 2506W4 | B5: 4.8527185 | C5: 2.0562789 | D5: 1.5177693 | E5: 1.2786703
A6: 2507W1 | B6: 4.5086023 | C6: 2.0072781 | D6: 1.5294624 | E6: 0.97186175
A7: 2507W2 | B7: 4.458581 | C7: 1.9545535 | D7: 1.5190208 | E7: 0.9850067
A8: 2507W3 | B8: 4.5426345 | C8: 1.9599012 | D8: 1.5089121 | E8: 1.0738211
A9: 2507W4 | B9: 4.7375393 | C9: 1.9793396 | D9: 1.6657297 | E9: 1.0924699
A10: 2508W1 | B10: 4.7202053 | C10: 1.9430781 | D10: 1.5955014 | E10: 1.1816258
A11: 2508W2 | B11: 4.7826727 | C11: 1.8732078 | D11: 1.6327524 | E11: 1.2767125
A12: 2508W3 | B12: 4.7728395 | C12: 1.8394383 | D12: 1.3939996 | E12: 1.5394016
A13: 2508W4 | B13: 4.6830676 | C13: 1.8102922 | D13: 1.3242847 | E13: 1.5484907
A14: 2508W5 | B14: 4.2895201 | C14: 1.7932278 | D14: 1.2898582 | E14: 1.206434
A26: 集团日均权益(亿元）
A27: 月份 | B27: 全部 | C27: 自开发客户 | D27: 集团客户 | E27: 自开发占比
A28: 2506W2 | B28: 4.8594317 | C28: 3.5962176 | D28: 1.2632141 | E28: =C28/B28 -> 0.74004901
A29: 2506W3 | B29: 4.8539346 | C29: 3.6019436 | D29: 1.251991 | E29: =C29/B29 -> 0.74206678
A30: 2506W4 | B30: 4.8527185 | C30: 3.6046372 | D30: 1.2480813 | E30: =C30/B30 -> 0.7428078
A31: 2507W1 | B31: 4.5086023 | C31: 3.5686539 | D31: 0.93994834 | E31: =C31/B31 -> 0.79152112
A32: 2507W2 | B32: 4.458581 | C32: 3.5064144 | D32: 0.95216664 | E32: =C32/B32 -> 0.78644178
A33: 2507W3 | B33: 4.5426345 | C33: 3.5010566 | D33: 1.0415779 | E33: =C33/B33 -> 0.77071061
A34: 2507W4 | B34: 4.7375393 | C34: 3.6744981 | D34: 1.0630412 | E34: =C34/B34 -> 0.77561322
A35: 2508W1 | B35: 4.7202053 | C35: 3.5697956 | D35: 1.1504097 | E35: =C35/B35 -> 0.75627974
A36: 2508W2 | B36: 4.7826727 | C36: 3.5364216 | D36: 1.2462511 | E36: =C36/B36 -> 0.73942371
A37: 2508W3 | B37: 4.7728395 | C37: 3.2617191 | D37: 1.5111204 | E37: =C37/B37 -> 0.68339175
A38: 2508W4 | B38: 4.6830676 | C38: 3.1593417 | D38: 1.5237259 | E38: =C38/B38 -> 0.67463081
A39: 2508W5 | B39: 4.2895201 | C39: 3.1054297 | D39: 1.1840904 | E39: =C39/B39 -> 0.72395738
A47: 客户期末权益（亿元）
A48: 月份 | B48: 期末权益(亿元） | C48: 净入金（万元） | D48: 盈亏（万元） | E48: 辅助列1 | F48: 辅助列2 | G48: 环比
A49: 2506W2 | B49: 5.05742 | C49: -727.8975 | D49: 3171.156 | E49: 30000 | F49: 0 | G49: =VLOOKUP(A49,[1]数据!A:K,11,0) -> 0.04704475
A50: 2506W3 | B50: 4.9091665 | C50: -2969.0529 | D50: 1513.1057 | E50: 30000 | F50: 0 | G50: =VLOOKUP(A50,[1]数据!A:K,11,0) -> -0.029314046
A51: 2506W4 | B51: 4.8892772 | C51: 1826.0524 | D51: -1953.261 | E51: 30000 | F51: 0 | G51: =VLOOKUP(A51,[1]数据!A:K,11,0) -> -0.0040514705
A52: 2507W1 | B52: 4.5239445 | C52: -3689.997 | D52: 129.7945 | E52: 30000 | F52: 0 | G52: =VLOOKUP(A52,[1]数据!A:K,11,0) -> -0.074721215
A53: 2507W2 | B53: 4.5605948 | C53: 588.79824 | D53: -136.003 | E53: 30000 | F53: 0 | G53: =VLOOKUP(A53,[1]数据!A:K,11,0) -> 0.0081014176
A54: 2507W3 | B54: 4.6929576 | C54: 1372.6419 | D54: 108.2533 | E54: 30000 | F54: 0 | G54: =VLOOKUP(A54,[1]数据!A:K,11,0) -> 0.029023129
A55: 2507W4 | B55: 4.8505254 | C55: 361.98433 | D55: 1366.964 | E55: 30000 | F55: 0 | G55: =VLOOKUP(A55,[1]数据!A:K,11,0) -> 0.033575394
A56: 2508W1 | B56: 4.5937399 | C56: -294.0544 | D56: -2065.1725 | E56: 30000 | F56: 0 | G56: =VLOOKUP(A56,[1]数据!A:K,11,0) -> -0.052939733
A57: 2508W2 | B57: 4.6482954 | C57: 888.40324 | D57: -203.6335 | E57: 30000 | F57: 0 | G57: =VLOOKUP(A57,[1]数据!A:K,11,0) -> 0.011876043
A58: 2508W3 | B58: 4.5154872 | C58: -839.52103 | D58: -405.135 | E58: 30000 | F58: 0 | G58: =VLOOKUP(A58,[1]数据!A:K,11,0) -> -0.028571382
...
